Workbook

Sheet Read Me
A1: MoSJE Portal — Design QC Tracker
A2: Status tracker for design-fidelity defects (dev-facing). Visual evidence lives in the annotated PDF report; design-improvement ideas live in the separate Design Suggestions doc.
A5: HOW TO USE
A6: 1. | B6: Each fidelity defect = one row in its portal's findings sheet. The annotated PDF shows the same ID on the image.
A7: 2. | B7: Severity / Category / Status are dropdowns; Severity auto-colours; Rollup aggregates automatically.
A8: 3. | B8: Figma URL and Live URL are full clickable links. Coverage tracks every screen's QC state.
A9: 4. | B9: Dev: filter Status = Open, fix, set Fixed. QC verifies -> Verified.
A10: 5. | B10: Design-side issues (design-bugs, redesigns, no-design screens) are NOT here — see Design Suggestions doc.
A12: SEVERITY | B12: Impact, not effort
A13: Blocker | B13: Breaks experience / brand / compliance. Cannot ship.
A14: Major | B14: Clearly wrong vs design; users notice.
A15: Minor | B15: Visible to a trained eye (2-7px, token drift).
A16: Nit | B16: Polish / sub-pixel.
A18: CATEGORIES | B18: Layout & Spacing · Color & Token · Typography · Components & States · Content & Iconography · Responsive & A11y
A19: DESIGN TRUTH | B19: Audited against DS Figma token values (see design-truth-tokens.md). DS brand primary = #003366.

Sheet Rollup
A1: Portal QC — Rollup
A4: Portal | B4: Total | C4: Blocker | D4: Major | E4: Minor | F4: Nit | G4: Open | H4: Fixed | I4: Verified
A5: eUtthan Admin | B5: =COUNTA('eUtthan Admin'!$A$2:$A$400) | C5: =COUNTIF('eUtthan Admin'!$E:$E,"Blocker") | D5: =COUNTIF('eUtthan Admin'!$E:$E,"Major") | E5: =COUNTIF('eUtthan Admin'!$E:$E,"Minor") | F5: =COUNTIF('eUtthan Admin'!$E:$E,"Nit") | G5: =COUNTIF('eUtthan Admin'!$J:$J,"Open") | H5: =COUNTIF('eUtthan Admin'!$J:$J,"Fixed") | I5: =COUNTIF('eUtthan Admin'!$J:$J,"Verified")

Sheet eUtthan Admin
A1: ID | B1: Screen | C1: Viewport | D1: Category | E1: Severity | F1: Issue (Design → Built) | G1: Recommended Fix (Dev) | H1: Figma URL | I1: Live URL | J1: Status | K1: Assignee | L1: Date | M1: Notes
A2: UTH-GLOBAL-001 | B2: Global — Common Elements | C2: 1440 | D2: Layout & Spacing | E2: Minor | F2: Figma: Height 40px, navy #003366 background. → Live: Height 38px (colour is correct). | G2: Increase the accessibility bar height from 38px to 40px. | H2: https://www.figma.com/design/gH2vQ62cfg4677YKWuOpLc/MoSJE-Portal--Handoff-?node-id=4226-39685 | J2: Open
A3: UTH-GLOBAL-002 | B3: Global — Common Elements | C3: 1440 | D3: Content & Iconography | E3: Major | F3: Figma: Two lines: 'Ministry of SJE' (14px/500/#1f2937) above the bold 'Department of SJE' headline (20px/700/#374151). → Live: Single line 'Ministry of SJE' at 20px/700/#374151 — the Department headline is absent. | G3: Add 'Department of Social Justice & Empowerment' (20px/700/#374151) as the main masthead headline; show the Ministry line above it at 14px/500/#1f2937. | H3: https://www.figma.com/design/gH2vQ62cfg4677YKWuOpLc/MoSJE-Portal--Handoff-?node-id=4226-39685 | J3: Open
A4: UTH-GLOBAL-003 | B4: Global — Common Elements | C4: 1440 | D4: Content & Iconography | E4: Major | F4: Figma: Centre-right of the masthead: Digital India logo + SAMAVESH lockup, with a 24px gap between them. → Live: No co-branding — the centre of the header is empty. | G4: Add the Digital India logo and the SAMAVESH lockup to the header centre, before the user profile. | H4: https://www.figma.com/design/gH2vQ62cfg4677YKWuOpLc/MoSJE-Portal--Handoff-?node-id=4226-39685 | J4: Open
A5: UTH-GLOBAL-004 | B5: Global — Common Elements | C5: 1440 | D5: Components & States | E5: Minor | F5: Figma: A hamburger/collapse control sits at the top-left of the header. → Live: No collapse control is shown in the header. | G5: Add the sidebar collapse (hamburger) control at the header's left edge. | H5: https://www.figma.com/design/gH2vQ62cfg4677YKWuOpLc/MoSJE-Portal--Handoff-?node-id=4226-39685 | J5: Open
A6: UTH-GLOBAL-005 | B6: Global — Common Elements | C6: 1440 | D6: Color & Token | E6: Major | F6: Figma: Active item: text #003366 · weight 400 · corner radius 16px · background #e5eff9. → Live: Active item: text #374151 · weight 700 · radius 8px (background correct; three properties deviate). | G6: Active sidebar item: text colour → #003366 · weight → 400 · corner radius → 16px. | H6: https://www.figma.com/design/gH2vQ62cfg4677YKWuOpLc/MoSJE-Portal--Handoff-?node-id=4226-39685 | J6: Open
A7: UTH-GLOBAL-006 | B7: Global — Common Elements | C7: 1440 | D7: Content & Iconography | E7: Minor | F7: Figma: Name with the role below it as plain text ('Admin', no punctuation); the avatar sits AFTER the text, at the far right. → Live: Avatar comes first, then the name; the role is wrapped in parentheses — '(Super Admin)'. | G7: Put the name and role first with the avatar to their right, and show the role as plain text without parentheses. | H7: https://www.figma.com/design/gH2vQ62cfg4677YKWuOpLc/MoSJE-Portal--Handoff-?node-id=4226-39685 | J7: Open
A8: UTH-GLOBAL-007 | B8: Global — Common Elements | C8: 1440 | D8: Typography | E8: Major | F8: Figma: All inputs and search fields use Noto Sans, like the rest of the portal. → Live: Search and text inputs render in Poppins on Login and across the Admin and Ministry screens. | G8: Set every input, select and search field to Noto Sans. | H8: https://www.figma.com/design/gH2vQ62cfg4677YKWuOpLc/MoSJE-Portal--Handoff-?node-id=4226-39685 | J8: Open
A9: UTH-GLOBAL-008 | B9: Global — Common Elements | C9: 1440 | D9: Components & States | E9: Minor | F9: Figma: Plus icon to the LEFT of the label; label 14px / 500 / line-height 20; padding 24-left / 16-right / 8 top & bottom; the plus is a separate 16×16 icon. → Live: Plus icon to the RIGHT; label 14px / 600 with a tight line-height; padding 18 / 12 / 0; the '+' is baked into the label text. | G9: On every Add button: plus icon on the left, label weight 500 / line-height 20, padding 24/16/8, and a real plus-icon element. | H9: https://www.figma.com/design/gH2vQ62cfg4677YKWuOpLc/MoSJE-Portal--Handoff-?node-id=4226-39685 | J9: Open
A10: UTH-GLOBAL-009 | B10: Global — Common Elements | C10: 1440 | D10: Typography | E10: Major | F10: Figma: 14px / 600 / colour #6b7280; cell padding 24px on the sides · 16px top & bottom; header sits on a #f9fafb band. → Live: Header text renders in #4b5563 with only 14px top/bottom padding (colour and vertical padding deviate; font-size 14px is correct). | G10: On every table header: text colour → #6b7280; cell padding 24px sides · 16px top/bottom. | H10: https://www.figma.com/design/gH2vQ62cfg4677YKWuOpLc/MoSJE-Portal--Handoff-?node-id=4226-39685 | J10: Open
A11: UTH-GLOBAL-010 | B11: Global — Common Elements | C11: 1440 | D11: Color & Token | E11: Major | F11: Figma: 14px / 400 / colour #374151; cell padding 24px on the sides · 16px top & bottom. → Live: Body cells render with a different colour (#4b5563, or pure #000 on some screens) and less top/bottom padding (16–20px). | G11: On every table body cell: text colour → #374151; cell padding 24px sides · 16px top/bottom. | H11: https://www.figma.com/design/gH2vQ62cfg4677YKWuOpLc/MoSJE-Portal--Handoff-?node-id=4226-39685 | J11: Open
A12: UTH-GLOBAL-011 | B12: Global — Common Elements | C12: 1440 | D12: Color & Token | E12: Minor | F12: Figma: The search bar and table sit directly on the page with a soft shadow — there is NO bordered card around them. → Live: The search and table are wrapped in a 1px hairline-bordered card. | G12: Remove the hairline card border around the search + table; use the soft shadow from the design. | H12: https://www.figma.com/design/gH2vQ62cfg4677YKWuOpLc/MoSJE-Portal--Handoff-?node-id=4226-39685 | J12: Open
A13: UTH-LOGIN-001 | B13: Login | C13: 1440 | D13: Components & States | E13: Blocker | F13: Figma: Navy government bar at the very top — flag + 'Government of India', 'Skip to Main Content', A−/A/A+ text resize, contrast toggle and language selector. → Live: The login page has no government bar at all (the signed-in pages do have it). | G13: Add the same government accessibility bar to the top of the login page. | H13: https://www.figma.com/design/gH2vQ62cfg4677YKWuOpLc/MoSJE-Portal--Handoff-?node-id=9018-36746 | I13: https://eutthan-admin-uat.mosje.in/login | J13: Open
A14: UTH-LOGIN-002 | B14: Login | C14: 1440 | D14: Content & Iconography | E14: Major | F14: Figma: Emblem + BETA tag + the full three-line lockup ending in the bold 'Department of Social Justice & Empowerment', plus the Digital India and SAMAVESH logos. → Live: Only the emblem with two lines; the BETA tag, Department line and both partner logos are missing. | G14: Show the complete masthead: BETA tag, full department lockup, and the Digital India + SAMAVESH logos. | H14: https://www.figma.com/design/gH2vQ62cfg4677YKWuOpLc/MoSJE-Portal--Handoff-?node-id=9018-36746 | I14: https://eutthan-admin-uat.mosje.in/login | J14: Open
A15: UTH-LOGIN-003 | B15: Login | C15: 1440 | D15: Color & Token | E15: Blocker | F15: Figma: A solid navy #003366 brand panel (~60% of the page): SAMAVESH logo + समावेश wordmark, orange divider, 'Justice. Equality. Dignity.' headline, a short description, and a bottom 'SIGNING INTO E-Utthaan' strip with a Change button. → Live: A pale-blue illustration fills the left side (~44%) — no navy panel, no SAMAVESH branding, no tagline and no 'SIGNING INTO' strip. | G15: Replace the illustration with the navy SAMAVESH brand panel, restore the ~60/40 split and the 'SIGNING INTO E-Utthaan' strip. | H15: https://www.figma.com/design/gH2vQ62cfg4677YKWuOpLc/MoSJE-Portal--Handoff-?node-id=9018-36746 | I15: https://eutthan-admin-uat.mosje.in/login | J15: Open
A16: UTH-LOGIN-004 | B16: Login | C16: 1440 | D16: Content & Iconography | E16: Major | F16: Figma: 'Log in to your account' — left-aligned at the top of the form. → Live: 'Log In' — centred, with the national emblem repeated above it. | G16: Use the heading 'Log in to your account', left-aligned, and remove the duplicate emblem above the form. | H16: https://www.figma.com/design/gH2vQ62cfg4677YKWuOpLc/MoSJE-Portal--Handoff-?node-id=9018-36746 | I16: https://eutthan-admin-uat.mosje.in/login | J16: Open
A17: UTH-LOGIN-005 | B17: Login | C17: 1440 | D17: Components & States | E17: Major | F17: Figma: 'User ID or Email' and 'Password' labels sit above their fields; inputs are 48px tall with a navy #003366 focus outline. → Live: No labels — only placeholder text inside the fields; inputs are 46px tall with no visible focus style. | G17: Add the two field labels above the inputs; input height 48px with a 2px navy #003366 focus outline. | H17: https://www.figma.com/design/gH2vQ62cfg4677YKWuOpLc/MoSJE-Portal--Handoff-?node-id=9018-36746 | I17: https://eutthan-admin-uat.mosje.in/login | J17: Open
A18: UTH-LOGIN-006 | B18: Login | C18: 1440 | D18: Components & States | E18: Minor | F18: Figma: Eye icon inside the password field — 24×24, grey #6b7280. → Live: The eye icon is smaller (~16px) and tight against the field edge with a small tap area. | G18: Use the 24px eye icon in grey #6b7280 with a comfortable tap area. | H18: https://www.figma.com/design/gH2vQ62cfg4677YKWuOpLc/MoSJE-Portal--Handoff-?node-id=9018-36746 | I18: https://eutthan-admin-uat.mosje.in/login | J18: Open
A19: UTH-LOGIN-007 | B19: Login | C19: 1440 | D19: Color & Token | E19: Minor | F19: Figma: Label 'Log In' · 48px tall · 8px corner radius · full form width. → Live: Label 'Sign In' · ~41px tall · ~6px radius. | G19: Change the label to 'Log In'; set height 48px and corner radius 8px. | H19: https://www.figma.com/design/gH2vQ62cfg4677YKWuOpLc/MoSJE-Portal--Handoff-?node-id=9018-36746 | I19: https://eutthan-admin-uat.mosje.in/login | J19: Open
A20: UTH-LOGIN-008 | B20: Login | C20: 1440 | D20: Content & Iconography | E20: Nit | F20: Figma: 'Forgot Password?' — with the question mark — right-aligned on the Password label row, in navy. → Live: 'Forgot Password' without the question mark. | G20: Add the question mark: 'Forgot Password?'. | H20: https://www.figma.com/design/gH2vQ62cfg4677YKWuOpLc/MoSJE-Portal--Handoff-?node-id=9018-36746 | I20: https://eutthan-admin-uat.mosje.in/login | J20: Open
A21: UTH-DASHBOARD-001 | B21: Admin / Dashboard | C21: 1440 | D21: Typography | E21: Minor | F21: Figma: Noto Sans 28px / 500 / line-height 36 / letter-spacing −0.28 / colour #374151. → Live: 30px / 600 / colour #1E3A5F (larger, bolder and a different colour). | G21: Set the page heading to 28px / 500 / #374151 / letter-spacing −0.28. | H21: https://www.figma.com/design/gH2vQ62cfg4677YKWuOpLc/MoSJE-Portal--Handoff-?node-id=4226-39685 | I21: https://eutthan-admin-uat.mosje.in/dashboard | J21: Open
A22: UTH-DASHBOARD-002 | B22: Admin / Dashboard | C22: 1440 | D22: Layout & Spacing | E22: Major | F22: Figma: The State and Financial-Year filters sit at the top of the page, next to the 'Dashboard' heading — they control everything below. → Live: The Financial-Year filter sits inside the 'Progress Report' panel header, although changing it also updates the four KPI cards above it. | G22: Move the Financial-Year filter to the top of the page next to the heading, as it affects the whole page. Applies to the Ministry dashboard as well. | H22: https://www.figma.com/design/gH2vQ62cfg4677YKWuOpLc/MoSJE-Portal--Handoff-?node-id=4226-39685 | I22: https://eutthan-admin-uat.mosje.in/dashboard | J22: Open
A23: UTH-DASHBOARD-003 | B23: Admin / Dashboard | C23: 1440 | D23: Components & States | E23: Minor | F23: Figma: Two filters at the top: a State dropdown ('All States') and the Financial-Year dropdown. → Live: Only the Financial-Year filter exists; there is no State filter. | G23: Show all the relevant filters. | H23: https://www.figma.com/design/gH2vQ62cfg4677YKWuOpLc/MoSJE-Portal--Handoff-?node-id=4226-39685 | I23: https://eutthan-admin-uat.mosje.in/dashboard | J23: Open
A24: UTH-DASHBOARD-004 | B24: Admin / Dashboard | C24: 1440 | D24: Typography | E24: Major | F24: Figma: Card label in regular weight (400) dark slate #374151; the value below in semibold dark slate #374151. → Live: Card labels render in bold, and all values render in bold navy (#003366 family) — heavier and bluer than the design. | G24: Card labels → regular 400 #374151; values → semibold #374151 (not navy, not extra bold). Applies to both dashboards. | H24: https://www.figma.com/design/gH2vQ62cfg4677YKWuOpLc/MoSJE-Portal--Handoff-?node-id=4226-39685 | I24: https://eutthan-admin-uat.mosje.in/dashboard | J24: Open
... A43: UTH-MIN-MINISTRY-PHYSICAL-PROGRESS-DATA-001 | B43: Ministry / Physical Progress Data | C43: 1440 | D43: Components & States | E43: Minor | F43: Figma: Two actions: 'Import Achievements Data' (outline) and 'Add Progress' (filled navy). → Live: A third button — 'Download Sample Template' — appears to the left of Import. | G43: Confirm whether the extra 'Download Sample Template' action is intended; the design shows two actions. | H43: https://www.figma.com/design/gH2vQ62cfg4677YKWuOpLc/MoSJE-Portal--Handoff-?node-id=4226-38368 | I43: https://eutthan-admin-uat.mosje.in/ministry/physical-progress-data | J43: Open

Sheet Coverage – eUtthan
A1: Screen | B1: Section | C1: Figma URL | D1: Has Design? | E1: Built? | F1: QC Status | G1: # Findings | H1: Notes
A2: Ministry / Dashboard | B2: Ministry | C2: https://www.figma.com/design/gH2vQ62cfg4677YKWuOpLc/MoSJE-Portal--Handoff-?node-id=4226-37114 | D2: Yes | E2: Yes | F2: Done | G2: =COUNTIF('eUtthan Admin'!$B:$B,$A2)
A3: Ministry / Manage Scheme | B3: Ministry | C3: https://www.figma.com/design/gH2vQ62cfg4677YKWuOpLc/MoSJE-Portal--Handoff-?node-id=4226-37360 | D3: Yes | E3: Yes | F3: Done | G3: =COUNTIF('eUtthan Admin'!$B:$B,$A3)
A4: Ministry / Manage Scheme (scrolled) | B4: Ministry | C4: https://www.figma.com/design/gH2vQ62cfg4677YKWuOpLc/MoSJE-Portal--Handoff-?node-id=4226-37568 | D4: Yes | F4: Not Started | G4: =COUNTIF('eUtthan Admin'!$B:$B,$A4)
A5: Ministry / Add | B5: Ministry | C5: https://www.figma.com/design/gH2vQ62cfg4677YKWuOpLc/MoSJE-Portal--Handoff-?node-id=4226-38254 | D5: Yes | F5: Not Started | G5: =COUNTIF('eUtthan Admin'!$B:$B,$A5)
A6: Ministry / Physical Progress Data | B6: Ministry | C6: https://www.figma.com/design/gH2vQ62cfg4677YKWuOpLc/MoSJE-Portal--Handoff-?node-id=4226-38368 | D6: Yes | E6: Yes | F6: Done | G6: =COUNTIF('eUtthan Admin'!$B:$B,$A6)
A7: Ministry / Manage Scheme (scrolled) | B7: Ministry | C7: https://www.figma.com/design/gH2vQ62cfg4677YKWuOpLc/MoSJE-Portal--Handoff-?node-id=4226-37796 | D7: Yes | F7: Not Started | G7: =COUNTIF('eUtthan Admin'!$B:$B,$A7)
A8: Ministry / Manage Scheme (scrolled) | B8: Ministry | C8: https://www.figma.com/design/gH2vQ62cfg4677YKWuOpLc/MoSJE-Portal--Handoff-?node-id=4226-38041 | D8: Yes | F8: Not Started | G8: =COUNTIF('eUtthan Admin'!$B:$B,$A8)
A9: Ministry / Physical Progress Data / Add | B9: Ministry | C9: https://www.figma.com/design/gH2vQ62cfg4677YKWuOpLc/MoSJE-Portal--Handoff-?node-id=4226-39568 | D9: Yes | F9: Not Started | G9: =COUNTIF('eUtthan Admin'!$B:$B,$A9)
A10: Ministry / Physical Progress Data / Import Excel | B10: Ministry | C10: https://www.figma.com/design/gH2vQ62cfg4677YKWuOpLc/MoSJE-Portal--Handoff-?node-id=4226-39128 | D10: Yes | F10: Not Started | G10: =COUNTIF('eUtthan Admin'!$B:$B,$A10)
A11: Ministry / Physical Progress Data / Import Excel (uploaded) | B11: Ministry | C11: https://www.figma.com/design/gH2vQ62cfg4677YKWuOpLc/MoSJE-Portal--Handoff-?node-id=4226-39348 | D11: Yes | F11: Not Started | G11: =COUNTIF('eUtthan Admin'!$B:$B,$A11)
A12: Ministry / Manage Outcome | B12: Ministry | C12: https://www.figma.com/design/gH2vQ62cfg4677YKWuOpLc/MoSJE-Portal--Handoff-?node-id=4226-38577 | D12: Yes | E12: Yes | F12: Done | G12: =COUNTIF('eUtthan Admin'!$B:$B,$A12)
A13: Ministry / Manage Outcome | B13: Ministry | C13: https://www.figma.com/design/gH2vQ62cfg4677YKWuOpLc/MoSJE-Portal--Handoff-?node-id=4226-38785 | D13: Yes | E13: Yes | F13: Done | G13: =COUNTIF('eUtthan Admin'!$B:$B,$A13)
A14: Ministry / Manage Outcome / Add | B14: Ministry | C14: https://www.figma.com/design/gH2vQ62cfg4677YKWuOpLc/MoSJE-Portal--Handoff-?node-id=4226-39013 | D14: Yes | F14: Not Started | G14: =COUNTIF('eUtthan Admin'!$B:$B,$A14)
A15: Admin / Dashboard | B15: Admin | C15: https://www.figma.com/design/gH2vQ62cfg4677YKWuOpLc/MoSJE-Portal--Handoff-?node-id=4226-39685 | D15: Yes | E15: Yes | F15: Done | G15: =COUNTIF('eUtthan Admin'!$B:$B,$A15)
A16: Admin / Financial Year | B16: Admin | C16: https://www.figma.com/design/gH2vQ62cfg4677YKWuOpLc/MoSJE-Portal--Handoff-?node-id=4226-40009 | D16: Yes | E16: Yes | F16: Done | G16: =COUNTIF('eUtthan Admin'!$B:$B,$A16)
A17: Admin / Financial Year / Add | B17: Admin | C17: https://www.figma.com/design/gH2vQ62cfg4677YKWuOpLc/MoSJE-Portal--Handoff-?node-id=4226-43777 | D17: Yes | F17: Not Started | G17: =COUNTIF('eUtthan Admin'!$B:$B,$A17)
A18: Admin / Financial Year | B18: Admin | C18: https://www.figma.com/design/gH2vQ62cfg4677YKWuOpLc/MoSJE-Portal--Handoff-?node-id=4226-40148 | D18: Yes | E18: Yes | F18: Done | G18: =COUNTIF('eUtthan Admin'!$B:$B,$A18)
A19: Admin / Financial Year / Edit | B19: Admin | C19: https://www.figma.com/design/gH2vQ62cfg4677YKWuOpLc/MoSJE-Portal--Handoff-?node-id=4226-44550 | D19: Yes | F19: Not Started | G19: =COUNTIF('eUtthan Admin'!$B:$B,$A19)
A20: Admin / Manage Ministry | B20: Admin | C20: https://www.figma.com/design/gH2vQ62cfg4677YKWuOpLc/MoSJE-Portal--Handoff-?node-id=4226-40288 | D20: Yes | E20: Yes | F20: Done | G20: =COUNTIF('eUtthan Admin'!$B:$B,$A20)
A21: Admin / Manage Ministry / Add | B21: Admin | C21: https://www.figma.com/design/gH2vQ62cfg4677YKWuOpLc/MoSJE-Portal--Handoff-?node-id=4226-43881 | D21: Yes | F21: Not Started | G21: =COUNTIF('eUtthan Admin'!$B:$B,$A21)
A22: Admin / Manage Scheme | B22: Admin | C22: https://www.figma.com/design/gH2vQ62cfg4677YKWuOpLc/MoSJE-Portal--Handoff-?node-id=4226-40449 | D22: Yes | E22: Yes | F22: Done | G22: =COUNTIF('eUtthan Admin'!$B:$B,$A22)
A23: Admin / Manage Scheme (scrolled) | B23: Admin | C23: https://www.figma.com/design/gH2vQ62cfg4677YKWuOpLc/MoSJE-Portal--Handoff-?node-id=4226-43077 | D23: Yes | F23: Not Started | G23: =COUNTIF('eUtthan Admin'!$B:$B,$A23)
A24: Admin / Manage Scheme / Add | B24: Admin | C24: https://www.figma.com/design/gH2vQ62cfg4677YKWuOpLc/MoSJE-Portal--Handoff-?node-id=4226-43990 | D24: Yes | F24: Not Started | G24: =COUNTIF('eUtthan Admin'!$B:$B,$A24)
A25: Admin / Manage Outcome | B25: Admin | C25: https://www.figma.com/design/gH2vQ62cfg4677YKWuOpLc/MoSJE-Portal--Handoff-?node-id=4226-40657 | D25: Yes | E25: Yes | F25: Done | G25: =COUNTIF('eUtthan Admin'!$B:$B,$A25)
A26: Admin / Manage Outcome (scrolled) | B26: Admin | C26: https://www.figma.com/design/gH2vQ62cfg4677YKWuOpLc/MoSJE-Portal--Handoff-?node-id=4226-43305 | D26: Yes | F26: Not Started | G26: =COUNTIF('eUtthan Admin'!$B:$B,$A26)
A27: Admin / Manage Outcome / Add | B27: Admin | C27: https://www.figma.com/design/gH2vQ62cfg4677YKWuOpLc/MoSJE-Portal--Handoff-?node-id=4226-44105 | D27: Yes | F27: Not Started | G27: =COUNTIF('eUtthan Admin'!$B:$B,$A27)
A28: Admin / Documents | B28: Admin | C28: https://www.figma.com/design/gH2vQ62cfg4677YKWuOpLc/MoSJE-Portal--Handoff-?node-id=4226-42902 | D28: Yes | E28: Yes | F28: Done | G28: =COUNTIF('eUtthan Admin'!$B:$B,$A28)
A29: Admin / Documents / Add | B29: Admin | C29: https://www.figma.com/design/gH2vQ62cfg4677YKWuOpLc/MoSJE-Portal--Handoff-?node-id=4226-44221 | D29: Yes | F29: Not Started | G29: =COUNTIF('eUtthan Admin'!$B:$B,$A29)
A30: Admin / Documents / Add | B30: Admin | C30: https://www.figma.com/design/gH2vQ62cfg4677YKWuOpLc/MoSJE-Portal--Handoff-?node-id=4226-44329 | D30: Yes | F30: Not Started | G30: =COUNTIF('eUtthan Admin'!$B:$B,$A30)
A31: Admin / Map Ministry / Mapped | B31: Admin | C31: https://www.figma.com/design/gH2vQ62cfg4677YKWuOpLc/MoSJE-Portal--Handoff-?node-id=4226-41073 | D31: Yes | E31: Yes | F31: Done | G31: =COUNTIF('eUtthan Admin'!$B:$B,$A31)
A32: Admin / Map Ministry / Unmapped | B32: Admin | C32: https://www.figma.com/design/gH2vQ62cfg4677YKWuOpLc/MoSJE-Portal--Handoff-?node-id=4226-41283 | D32: Yes | F32: Not Started | G32: =COUNTIF('eUtthan Admin'!$B:$B,$A32)
A33: Admin / Map Schemes / Map | B33: Admin | C33: https://www.figma.com/design/gH2vQ62cfg4677YKWuOpLc/MoSJE-Portal--Handoff-?node-id=4226-42430 | D33: Yes | F33: Not Started | G33: =COUNTIF('eUtthan Admin'!$B:$B,$A33)
A34: Admin / Map Schemes / Mapped | B34: Admin | C34: https://www.figma.com/design/gH2vQ62cfg4677YKWuOpLc/MoSJE-Portal--Handoff-?node-id=4226-41490 | D34: Yes | F34: Not Started | G34: =COUNTIF('eUtthan Admin'!$B:$B,$A34)
A35: Admin / Map Schemes / Mapped | B35: Admin | C35: https://www.figma.com/design/gH2vQ62cfg4677YKWuOpLc/MoSJE-Portal--Handoff-?node-id=4226-41730 | D35: Yes | F35: Not Started | G35: =COUNTIF('eUtthan Admin'!$B:$B,$A35)
A36: Admin / Map Schemes / Map | B36: Admin | C36: https://www.figma.com/design/gH2vQ62cfg4677YKWuOpLc/MoSJE-Portal--Handoff-?node-id=4226-42650 | D36: Yes | F36: Not Started | G36: =COUNTIF('eUtthan Admin'!$B:$B,$A36)
A37: Admin / Map Schemes / Mapped | B37: Admin | C37: https://www.figma.com/design/gH2vQ62cfg4677YKWuOpLc/MoSJE-Portal--Handoff-?node-id=4226-41970 | D37: Yes | F37: Not Started | G37: =COUNTIF('eUtthan Admin'!$B:$B,$A37)
A38: Admin / Map Schemes / Unmap | B38: Admin | C38: https://www.figma.com/design/gH2vQ62cfg4677YKWuOpLc/MoSJE-Portal--Handoff-?node-id=4226-42210 | D38: Yes | F38: Not Started | G38: =COUNTIF('eUtthan Admin'!$B:$B,$A38)
A39: Admin / Manage User | B39: Admin | C39: https://www.figma.com/design/gH2vQ62cfg4677YKWuOpLc/MoSJE-Portal--Handoff-?node-id=4226-40865 | D39: Yes | E39: Yes | F39: Done | G39: =COUNTIF('eUtthan Admin'!$B:$B,$A39)
A40: Admin / Manage User | B40: Admin | C40: https://www.figma.com/design/gH2vQ62cfg4677YKWuOpLc/MoSJE-Portal--Handoff-?node-id=4226-43533 | D40: Yes | E40: Yes | F40: Done | G40: =COUNTIF('eUtthan Admin'!$B:$B,$A40)
...
