Workbook

Sheet Read Me
A1: MoSJE Portal — Design QC Tracker
A2: Status tracker for design-fidelity defects (dev-facing). Visual evidence lives in the annotated PDF report; design-improvement ideas live in the separate Design Suggestions doc.
A5: HOW TO USE
A6: 1. | B6: Each fidelity defect = one row in its portal's findings sheet. The annotated PDF shows the same ID on the image.
A7: 2. | B7: Severity / Category / Status are dropdowns; Severity auto-colours; Rollup aggregates automatically.
A8: 3. | B8: Figma URL and Live URL are full clickable links. Coverage tracks every screen's QC state.
A9: 4. | B9: Dev: filter Status = Open, fix, set Fixed. QC verifies -> Verified.
A10: 5. | B10: Design-side issues (design-bugs, redesigns, no-design screens) are NOT here — see Design Suggestions doc.
A12: SEVERITY | B12: Impact, not effort
A13: Blocker | B13: Breaks experience / brand / compliance. Cannot ship.
A14: Major | B14: Clearly wrong vs design; users notice.
A15: Minor | B15: Visible to a trained eye (2-7px, token drift).
A16: Nit | B16: Polish / sub-pixel.
A18: CATEGORIES | B18: Layout & Spacing · Color & Token · Typography · Components & States · Content & Iconography · Responsive & A11y
A19: DESIGN TRUTH | B19: Audited against DS Figma token values (see design-truth-tokens.md). DS brand primary = #003366.

Sheet Rollup
A1: Portal QC — Rollup
A4: Portal | B4: Total | C4: Blocker | D4: Major | E4: Minor | F4: Nit | G4: Open | H4: Fixed | I4: Verified
A5: eUtthan Admin | B5: =COUNTA('eUtthan Admin'!$A$2:$A$400) | C5: =COUNTIF('eUtthan Admin'!$D:$D,"Blocker") | D5: =COUNTIF('eUtthan Admin'!$D:$D,"Major") | E5: =COUNTIF('eUtthan Admin'!$D:$D,"Minor") | F5: =COUNTIF('eUtthan Admin'!$D:$D,"Nit") | G5: =COUNTIF('eUtthan Admin'!$I:$I,"Open") | H5: =COUNTIF('eUtthan Admin'!$I:$I,"Fixed") | I5: =COUNTIF('eUtthan Admin'!$I:$I,"Verified")
A6: NHAPOA | B6: =COUNTA('NHAPOA'!$A$2:$A$400) | C6: =COUNTIF('NHAPOA'!$D:$D,"Blocker") | D6: =COUNTIF('NHAPOA'!$D:$D,"Major") | E6: =COUNTIF('NHAPOA'!$D:$D,"Minor") | F6: =COUNTIF('NHAPOA'!$D:$D,"Nit") | G6: =COUNTIF('NHAPOA'!$I:$I,"Open") | H6: =COUNTIF('NHAPOA'!$I:$I,"Fixed") | I6: =COUNTIF('NHAPOA'!$I:$I,"Verified")
A7: TG | B7: =COUNTA('TG'!$A$2:$A$400) | C7: =COUNTIF('TG'!$D:$D,"Blocker") | D7: =COUNTIF('TG'!$D:$D,"Major") | E7: =COUNTIF('TG'!$D:$D,"Minor") | F7: =COUNTIF('TG'!$D:$D,"Nit") | G7: =COUNTIF('TG'!$I:$I,"Open") | H7: =COUNTIF('TG'!$I:$I,"Fixed") | I7: =COUNTIF('TG'!$I:$I,"Verified")
A8: SMILE Beggary | B8: =COUNTA('SMILE Beggary'!$A$2:$A$999) | C8: =COUNTIF('SMILE Beggary'!$D:$D,"Blocker") | D8: =COUNTIF('SMILE Beggary'!$D:$D,"Major") | E8: =COUNTIF('SMILE Beggary'!$D:$D,"Minor") | F8: =COUNTIF('SMILE Beggary'!$D:$D,"Nit") | G8: =COUNTIF('SMILE Beggary'!$I:$I,"Open") | H8: =COUNTIF('SMILE Beggary'!$I:$I,"Fixed") | I8: =COUNTIF('SMILE Beggary'!$I:$I,"Verified")
A9: NMBA | B9: =COUNTA('NMBA'!$A$2:$A$999) | C9: =COUNTIF('NMBA'!$D:$D,"Blocker") | D9: =COUNTIF('NMBA'!$D:$D,"Major") | E9: =COUNTIF('NMBA'!$D:$D,"Minor") | F9: =COUNTIF('NMBA'!$D:$D,"Nit") | G9: =COUNTIF('NMBA'!$I:$I,"Open") | H9: =COUNTIF('NMBA'!$I:$I,"Fixed") | I9: =COUNTIF('NMBA'!$I:$I,"Verified")

Sheet eUtthan Admin
A1: ID | B1: Screen | C1: Category | D1: Severity | E1: Issue (Design → Built) | F1: Recommended Fix (Dev) | G1: Figma URL | H1: Live URL | I1: Status | J1: Assignee | K1: Date | L1: Notes
A2: UTH-GLOBAL-001 | B2: Global — Common Elements | C2: Layout & Spacing | D2: Minor | E2: Figma: Height 40px, navy #003366 background. → Live: Height 38px (colour is correct). | F2: Increase the accessibility bar height from 38px to 40px. | G2: https://www.figma.com/design/gH2vQ62cfg4677YKWuOpLc/MoSJE-Portal--Handoff-?node-id=4226-39685 | I2: Open
A3: UTH-GLOBAL-002 | B3: Global — Common Elements | C3: Content & Iconography | D3: Major | E3: Figma: Two lines: 'Ministry of SJE' (14px/500/#1f2937) above the bold 'Department of SJE' headline (20px/700/#374151). → Live: Single line 'Ministry of SJE' at 20px/700/#374151 — the Department headline is absent. | F3: Add 'Department of Social Justice & Empowerment' (20px/700/#374151) as the main masthead headline; show the Ministry line above it at 14px/500/#1f2937. | G3: https://www.figma.com/design/gH2vQ62cfg4677YKWuOpLc/MoSJE-Portal--Handoff-?node-id=4226-39685 | I3: Open
A4: UTH-GLOBAL-003 | B4: Global — Common Elements | C4: Content & Iconography | D4: Major | E4: Figma: Centre-right of the masthead: Digital India logo + SAMAVESH lockup, with a 24px gap between them. → Live: No co-branding — the centre of the header is empty. | F4: Add the Digital India logo and the SAMAVESH lockup to the header centre, before the user profile. | G4: https://www.figma.com/design/gH2vQ62cfg4677YKWuOpLc/MoSJE-Portal--Handoff-?node-id=4226-39685 | I4: Open
A5: UTH-GLOBAL-004 | B5: Global — Common Elements | C5: Components & States | D5: Minor | E5: Figma: A hamburger/collapse control sits at the top-left of the header. → Live: No collapse control is shown in the header. | F5: Add the sidebar collapse (hamburger) control at the header's left edge. | G5: https://www.figma.com/design/gH2vQ62cfg4677YKWuOpLc/MoSJE-Portal--Handoff-?node-id=4226-39685 | I5: Open
A6: UTH-GLOBAL-005 | B6: Global — Common Elements | C6: Color & Token | D6: Major | E6: Figma: Active item: text #003366 · weight 400 · corner radius 16px · background #e5eff9. → Live: Active item: text #374151 · weight 700 · radius 8px (background correct; three properties deviate). | F6: Active sidebar item: text colour → #003366 · weight → 400 · corner radius → 16px. | G6: https://www.figma.com/design/gH2vQ62cfg4677YKWuOpLc/MoSJE-Portal--Handoff-?node-id=4226-39685 | I6: Open
A7: UTH-GLOBAL-006 | B7: Global — Common Elements | C7: Content & Iconography | D7: Minor | E7: Figma: Name with the role below it as plain text ('Admin', no punctuation); the avatar sits AFTER the text, at the far right. → Live: Avatar comes first, then the name; the role is wrapped in parentheses — '(Super Admin)'. | F7: Put the name and role first with the avatar to their right, and show the role as plain text without parentheses. | G7: https://www.figma.com/design/gH2vQ62cfg4677YKWuOpLc/MoSJE-Portal--Handoff-?node-id=4226-39685 | I7: Open
A8: UTH-GLOBAL-007 | B8: Global — Common Elements | C8: Typography | D8: Major | E8: Figma: All inputs and search fields use Noto Sans, like the rest of the portal. → Live: Search and text inputs render in Poppins on Login and across the Admin and Ministry screens. | F8: Set every input, select and search field to Noto Sans. | G8: https://www.figma.com/design/gH2vQ62cfg4677YKWuOpLc/MoSJE-Portal--Handoff-?node-id=4226-39685 | I8: Open
A9: UTH-GLOBAL-008 | B9: Global — Common Elements | C9: Components & States | D9: Minor | E9: Figma: Plus icon to the LEFT of the label; label 14px / 500 / line-height 20; padding 24-left / 16-right / 8 top & bottom; the plus is a separate 16×16 icon. → Live: Plus icon to the RIGHT; label 14px / 600 with a tight line-height; padding 18 / 12 / 0; the '+' is baked into the label text. | F9: On every Add button: plus icon on the left, label weight 500 / line-height 20, padding 24/16/8, and a real plus-icon element. | G9: https://www.figma.com/design/gH2vQ62cfg4677YKWuOpLc/MoSJE-Portal--Handoff-?node-id=4226-39685 | I9: Open
A10: UTH-GLOBAL-009 | B10: Global — Common Elements | C10: Typography | D10: Major | E10: Figma: 14px / 600 / colour #6b7280; cell padding 24px on the sides · 16px top & bottom; header sits on a #f9fafb band. → Live: Header text renders in #4b5563 with only 14px top/bottom padding (colour and vertical padding deviate; font-size 14px is correct). | F10: On every table header: text colour → #6b7280; cell padding 24px sides · 16px top/bottom. | G10: https://www.figma.com/design/gH2vQ62cfg4677YKWuOpLc/MoSJE-Portal--Handoff-?node-id=4226-39685 | I10: Open
A11: UTH-GLOBAL-010 | B11: Global — Common Elements | C11: Color & Token | D11: Major | E11: Figma: 14px / 400 / colour #374151; cell padding 24px on the sides · 16px top & bottom. → Live: Body cells render with a different colour (#4b5563, or pure #000 on some screens) and less top/bottom padding (16–20px). | F11: On every table body cell: text colour → #374151; cell padding 24px sides · 16px top/bottom. | G11: https://www.figma.com/design/gH2vQ62cfg4677YKWuOpLc/MoSJE-Portal--Handoff-?node-id=4226-39685 | I11: Open
A12: UTH-GLOBAL-011 | B12: Global — Common Elements | C12: Color & Token | D12: Minor | E12: Figma: The search bar and table sit directly on the page with a soft shadow — there is NO bordered card around them. → Live: The search and table are wrapped in a 1px hairline-bordered card. | F12: Remove the hairline card border around the search + table; use the soft shadow from the design. | G12: https://www.figma.com/design/gH2vQ62cfg4677YKWuOpLc/MoSJE-Portal--Handoff-?node-id=4226-39685 | I12: Open
A13: UTH-LOGIN-001 | B13: Login | C13: Components & States | D13: Blocker | E13: Figma: Navy government bar at the very top — flag + 'Government of India', 'Skip to Main Content', A−/A/A+ text resize, contrast toggle and language selector. → Live: The login page has no government bar at all (the signed-in pages do have it). | F13: Add the same government accessibility bar to the top of the login page. | G13: https://www.figma.com/design/gH2vQ62cfg4677YKWuOpLc/MoSJE-Portal--Handoff-?node-id=9018-36746 | H13: https://eutthan-admin-uat.mosje.in/login | I13: Open
A14: UTH-LOGIN-002 | B14: Login | C14: Content & Iconography | D14: Major | E14: Figma: Emblem + BETA tag + the full three-line lockup ending in the bold 'Department of Social Justice & Empowerment', plus the Digital India and SAMAVESH logos. → Live: Only the emblem with two lines; the BETA tag, Department line and both partner logos are missing. | F14: Show the complete masthead: BETA tag, full department lockup, and the Digital India + SAMAVESH logos. | G14: https://www.figma.com/design/gH2vQ62cfg4677YKWuOpLc/MoSJE-Portal--Handoff-?node-id=9018-36746 | H14: https://eutthan-admin-uat.mosje.in/login | I14: Open
A15: UTH-LOGIN-003 | B15: Login | C15: Color & Token | D15: Blocker | E15: Figma: A solid navy #003366 brand panel (~60% of the page): SAMAVESH logo + समावेश wordmark, orange divider, 'Justice. Equality. Dignity.' headline, a short description, and a bottom 'SIGNING INTO E-Utthaan' strip with a Change button. → Live: A pale-blue illustration fills the left side (~44%) — no navy panel, no SAMAVESH branding, no tagline and no 'SIGNING INTO' strip. | F15: Replace the illustration with the navy SAMAVESH brand panel, restore the ~60/40 split and the 'SIGNING INTO E-Utthaan' strip. | G15: https://www.figma.com/design/gH2vQ62cfg4677YKWuOpLc/MoSJE-Portal--Handoff-?node-id=9018-36746 | H15: https://eutthan-admin-uat.mosje.in/login | I15: Open
A16: UTH-LOGIN-004 | B16: Login | C16: Content & Iconography | D16: Major | E16: Figma: 'Log in to your account' — left-aligned at the top of the form. → Live: 'Log In' — centred, with the national emblem repeated above it. | F16: Use the heading 'Log in to your account', left-aligned, and remove the duplicate emblem above the form. | G16: https://www.figma.com/design/gH2vQ62cfg4677YKWuOpLc/MoSJE-Portal--Handoff-?node-id=9018-36746 | H16: https://eutthan-admin-uat.mosje.in/login | I16: Open
A17: UTH-LOGIN-005 | B17: Login | C17: Components & States | D17: Major | E17: Figma: 'User ID or Email' and 'Password' labels sit above their fields; inputs are 48px tall with a navy #003366 focus outline. → Live: No labels — only placeholder text inside the fields; inputs are 46px tall with no visible focus style. | F17: Add the two field labels above the inputs; input height 48px with a 2px navy #003366 focus outline. | G17: https://www.figma.com/design/gH2vQ62cfg4677YKWuOpLc/MoSJE-Portal--Handoff-?node-id=9018-36746 | H17: https://eutthan-admin-uat.mosje.in/login | I17: Open
A18: UTH-LOGIN-006 | B18: Login | C18: Components & States | D18: Minor | E18: Figma: Eye icon inside the password field — 24×24, grey #6b7280. → Live: The eye icon is smaller (~16px) and tight against the field edge with a small tap area. | F18: Use the 24px eye icon in grey #6b7280 with a comfortable tap area. | G18: https://www.figma.com/design/gH2vQ62cfg4677YKWuOpLc/MoSJE-Portal--Handoff-?node-id=9018-36746 | H18: https://eutthan-admin-uat.mosje.in/login | I18: Open
A19: UTH-LOGIN-007 | B19: Login | C19: Color & Token | D19: Minor | E19: Figma: Label 'Log In' · 48px tall · 8px corner radius · full form width. → Live: Label 'Sign In' · ~41px tall · ~6px radius. | F19: Change the label to 'Log In'; set height 48px and corner radius 8px. | G19: https://www.figma.com/design/gH2vQ62cfg4677YKWuOpLc/MoSJE-Portal--Handoff-?node-id=9018-36746 | H19: https://eutthan-admin-uat.mosje.in/login | I19: Open
A20: UTH-LOGIN-008 | B20: Login | C20: Content & Iconography | D20: Nit | E20: Figma: 'Forgot Password?' — with the question mark — right-aligned on the Password label row, in navy. → Live: 'Forgot Password' without the question mark. | F20: Add the question mark: 'Forgot Password?'. | G20: https://www.figma.com/design/gH2vQ62cfg4677YKWuOpLc/MoSJE-Portal--Handoff-?node-id=9018-36746 | H20: https://eutthan-admin-uat.mosje.in/login | I20: Open
A21: UTH-DASHBOARD-001 | B21: Admin / Dashboard | C21: Typography | D21: Minor | E21: Figma: Noto Sans 28px / 500 / line-height 36 / letter-spacing −0.28 / colour #374151. → Live: 30px / 600 / colour #1E3A5F (larger, bolder and a different colour). | F21: Set the page heading to 28px / 500 / #374151 / letter-spacing −0.28. | G21: https://www.figma.com/design/gH2vQ62cfg4677YKWuOpLc/MoSJE-Portal--Handoff-?node-id=4226-39685 | H21: https://eutthan-admin-uat.mosje.in/dashboard | I21: Open
A22: UTH-DASHBOARD-002 | B22: Admin / Dashboard | C22: Layout & Spacing | D22: Major | E22: Figma: The State and Financial-Year filters sit at the top of the page, next to the 'Dashboard' heading — they control everything below. → Live: The Financial-Year filter sits inside the 'Progress Report' panel header, although changing it also updates the four KPI cards above it. | F22: Move the Financial-Year filter to the top of the page next to the heading, as it affects the whole page. Applies to the Ministry dashboard as well. | G22: https://www.figma.com/design/gH2vQ62cfg4677YKWuOpLc/MoSJE-Portal--Handoff-?node-id=4226-39685 | H22: https://eutthan-admin-uat.mosje.in/dashboard | I22: Open
A23: UTH-DASHBOARD-003 | B23: Admin / Dashboard | C23: Components & States | D23: Minor | E23: Figma: Two filters at the top: a State dropdown ('All States') and the Financial-Year dropdown. → Live: Only the Financial-Year filter exists; there is no State filter. | F23: Show all the relevant filters. | G23: https://www.figma.com/design/gH2vQ62cfg4677YKWuOpLc/MoSJE-Portal--Handoff-?node-id=4226-39685 | H23: https://eutthan-admin-uat.mosje.in/dashboard | I23: Open
A24: UTH-DASHBOARD-004 | B24: Admin / Dashboard | C24: Typography | D24: Major | E24: Figma: Card label in regular weight (400) dark slate #374151; the value below in semibold dark slate #374151. → Live: Card labels render in bold, and all values render in bold navy (#003366 family) — heavier and bluer than the design. | F24: Card labels → regular 400 #374151; values → semibold #374151 (not navy, not extra bold). Applies to both dashboards. | G24: https://www.figma.com/design/gH2vQ62cfg4677YKWuOpLc/MoSJE-Portal--Handoff-?node-id=4226-39685 | H24: https://eutthan-admin-uat.mosje.in/dashboard | I24: Open
... A43: UTH-MIN-MINISTRY-PHYSICAL-PROGRESS-DATA-001 | B43: Ministry / Physical Progress Data | C43: Components & States | D43: Minor | E43: Figma: Two actions: 'Import Achievements Data' (outline) and 'Add Progress' (filled navy). → Live: A third button — 'Download Sample Template' — appears to the left of Import. | F43: Confirm whether the extra 'Download Sample Template' action is intended; the design shows two actions. | G43: https://www.figma.com/design/gH2vQ62cfg4677YKWuOpLc/MoSJE-Portal--Handoff-?node-id=4226-38368 | H43: https://eutthan-admin-uat.mosje.in/ministry/physical-progress-data | I43: Open

Sheet SMILE Beggary
A1: ID | B1: Screen | C1: Category | D1: Severity | E1: Issue (Design → Built) | F1: Recommended Fix (Dev) | G1: Figma URL | H1: Live URL | I1: Status | J1: Assignee | K1: Date | L1: Notes | M1: Scope
A2: SMB-GLOBAL-001 | B2: Global · The current page is a solid gold chip; the design outlines it in navy | C2: Color & Token | D2: Major | E2: Figma: The active page is a white chip with a 1px navy #003366 outline and radius 8, its number in #1F2937. Every other page number is plain text on no fill. (Measured on the Users frame's own .page instances.) Built: The active page is a solid gold #F5BE14 chip with black text. Gold appears nowhere else in the interface as a selected state, and it is not among the colours the SMILE Figma variables publish for an active control. | F2: Draw the active page as the design does — white fill, 1px #003366 outline, radius 8 — or, if a filled active state is wanted, fill it with the primary navy and set the number in white. Gold reads as a warning beside the Awaited and Pending chips these same tables carry. (Corrected 2026-09-10: an earlier draft of this finding called the build chip saffron/orange and the design chip navy-filled; measured, the build is #F5BE14 and the design is white with a navy outline.) | G2: https://www.figma.com/design/evmNmlK8g4VYwJVu2FwSGV/MoSJE-Portal--Handoff-?node-id=8664-51029 | H2: https://smile-admin-dev.mosje.in/users | I2: Open | L2: env: dev · Scope: Global — fix once, lands everywhere | M2: Global
A3: SMB-GLOBAL-002 | B3: Global · The two halves of the pagination row are swapped | C3: Layout & Spacing | D3: Major | E3: Figma: Page numbers sit on the left, the record count and per-page selector on the right. Built: The record count is on the left and the page numbers plus per-page selector are on the right — the mirror image, on every list screen. | F3: Return to the design's order: page numbers left, count and per-page right, so the control a reader reaches for is in the same place on every list in the estate. | G3: https://www.figma.com/design/evmNmlK8g4VYwJVu2FwSGV/MoSJE-Portal--Handoff-?node-id=8664-51029 | H3: https://smile-admin-dev.mosje.in/users | I3: Open | L3: env: dev · Scope: Global — fix once, lands everywhere | M3: Global
A4: SMB-GLOBAL-003 | B4: Global · The same table header is three different sizes depending on the screen | C4: Typography | D4: Major | E4: Figma: One column-header style: Title Case at the body size in the primary navy, semibold. Built: Measured across all 17 list screens: the header cell renders at 12px on fourteen of them, 14px on Users and City Profiling, and 11px on Performance Statistics. All of them are uppercased by text-transform and letterspaced, so the DOM says 'Name' and the screen says 'NAME'. On Notifications the twelve headers wrap onto two lines to fit. | F4: Pick one column-header style and bind every table to it — label-1 (14/20 Medium) is the closest published match. Three sizes for one element is what makes a set of list screens read as three different products; the uppercase is a separate decision to make deliberately, since it costs legibility and is what forces the two-line wrap. | G4: https://www.figma.com/design/evmNmlK8g4VYwJVu2FwSGV/MoSJE-Portal--Handoff-?node-id=8664-51029 | H4: https://smile-admin-dev.mosje.in/users | I4: Open | L4: env: dev · Scope: Global — fix once, lands everywhere | M4: Global
A5: SMB-GLOBAL-004 | B5: Global · The sidebar is a different typeface and size from the design | C5: Typography | D5: Major | E5: Figma: Every navigation label is Noto Sans at 14px — measured off the design frame's own text nodes (Dashboard, City Profiling, Performance Statistics, Users, Roles all report 14). Built: The build renders the sidebar in the system stack (-apple-system) at 15px. Measured on Users, 48 of the 181 on-canvas elements are in that stack and every one of them is a navigation item; across all 51 captures it is 2,128 elements. | F5: Set the sidebar to Noto Sans at 14px to match the design. The likely cause is a navigation component left on the framework's default sans stack rather than the app's. | G5: https://www.figma.com/design/evmNmlK8g4VYwJVu2FwSGV/MoSJE-Portal--Handoff-?node-id=8664-51029 | H5: https://smile-admin-dev.mosje.in/users | I5: Open | L5: env: dev · Scope: Global — fix once, lands everywhere | M5: Global
A6: SMB-GLOBAL-005 | B6: Global · Every page title is smaller, heavier and a different colour than the design | C6: Typography | D6: Major | E6: Figma: The page heading is 28px Medium in the ink colour #1f2937. Built: 24px Bold in #111827 — measured identically on Users, Roles, Permissions, Notifications, Fund Monitoring, Consent Forms, Audit Log, Swashraya and IA List. Bold at a smaller size reads as a different level in the hierarchy from the one the design set. | F6: Set the page heading to 28px Medium #1f2937 in the shared page-header component, which fixes it everywhere at once. | G6: https://www.figma.com/design/evmNmlK8g4VYwJVu2FwSGV/MoSJE-Portal--Handoff-?node-id=8664-51029 | H6: https://smile-admin-dev.mosje.in/users | I6: Open | L6: env: dev · Scope: Global — fix once, lands everywhere | M6: Global
A7: SMB-GLOBAL-006 | B7: Global · KPI card labels are uppercase, and some are truncated | C7: Typography | D7: Minor | E7: Figma: Card labels are Title Case at the label size, sitting above the figure — 'Total Users', 'Identified/Surveyed', 'Total Notification'. Built: Labels are uppercase and smaller, and where the label is long it is cut off with an ellipsis: the Notifications page reads 'TOTAL NOTIFIC…'. | F7: Set the label to Title Case at label-1 (14/20 Medium) and let the card grow to its content. A truncated label is a label the reader cannot use. | G7: https://www.figma.com/design/evmNmlK8g4VYwJVu2FwSGV/MoSJE-Portal--Handoff-?node-id=51830-237991 | H7: https://smile-admin-dev.mosje.in/notifications | I7: Open | L7: env: dev · Scope: Global — fix once, lands everywhere | M7: Global
A8: SMB-GLOBAL-007 | B8: Global · The KPI icon tile is 36px where the design draws 56px | C8: Layout & Spacing | D8: Minor | E8: Figma: The icon sits in a rounded tile filled with a light tint of that metric's colour, measured at 56 x 56 on the Beneficiary List frame. Built: The same tinted tile is there, at 36 x 36 — about a third of the drawn area. With the label also dropping to 11px uppercase (G05), the whole card reads a size smaller than designed. | F8: Set the icon tile to 56 x 56 with the same tint. (Corrected 2026-09-10: an earlier draft of this finding said the build had no tinted chip at all. It has one; it is smaller. The claim came from a text-only extraction that does not see the icon element — the screenshots do.) | G8: https://www.figma.com/design/evmNmlK8g4VYwJVu2FwSGV/MoSJE-Portal--Handoff-?node-id=8664-57337 | H8: https://smile-admin-dev.mosje.in/persons | I8: Open | L8: env: dev · Scope: Global — fix once, lands everywhere | M8: Global
A9: SMB-GLOBAL-008 | B9: Global · The page-level export moved out of the header and became two buttons | C9: Components & States | D9: Minor | E9: Figma: One 'Export' control sits on the header row at x=1349, level with the page title — on Beneficiary List, Consent Forms, Notifications, Survey Locations, Surveyor Mappings and the Dashboard. Users and Roles carry no export in the design at all. Built: Two buttons, 'CSV' and 'PDF', sit above the title row at the top-right of the content area, out of line with the heading — including on Users and Roles, where the design draws none. The Beneficiary List has three: Download All (CSV), CSV and PDF. | F9: Return a single Export control to the header row aligned with the H1, and put the format choice inside it, so the header's action slot reads the same on every screen. Where the design has no export and the build does (Users, Roles), decide which is right and make both say so. | G9: https://www.figma.com/design/evmNmlK8g4VYwJVu2FwSGV/MoSJE-Portal--Handoff-?node-id=8664-57337 | H9: https://smile-admin-dev.mosje.in/persons | I9: Open | L9: env: dev · Scope: Global — fix once, lands everywhere | M9: Global
A10: SMB-GLOBAL-009 | B10: Global · The masthead's contrast control is now a light/dark toggle | C10: Components & States | D10: Minor | E10: Figma: The accessibility bar carries a contrast control (the half-filled circle) beside the accessibility icon. Built: That slot is a crescent moon labelled 'Light-Dark'; the neighbouring control is labelled 'Invert Colors'. A theme switch and a contrast control are different affordances. | F10: Confirm the intent. GIGW expects a contrast affordance in the masthead; if light/dark replaces it, the contrast requirement needs to be met somewhere the reader can find it, and the design should be updated to match. | G10: https://www.figma.com/design/evmNmlK8g4VYwJVu2FwSGV/MoSJE-Portal--Handoff-?node-id=8664-51029 | H10: https://smile-admin-dev.mosje.in/users | I10: Open | L10: env: dev · Scope: Global — fix once, lands everywhere | M10: Global
A11: SMB-GLOBAL-010 | B11: Global · The line under every page title is a size down and a lighter grey | C11: Typography | D11: Minor | E11: Figma: The description under the heading is 16px Regular in #374151. Built: 14px Regular in #6b7280, on every screen measured. | F11: Set it to 16px #374151 in the same page-header component. | G11: https://www.figma.com/design/evmNmlK8g4VYwJVu2FwSGV/MoSJE-Portal--Handoff-?node-id=8664-51029 | H11: https://smile-admin-dev.mosje.in/users | I11: Open | L11: env: dev · Scope: Global — fix once, lands everywhere | M11: Global
A12: SMB-GLOBAL-011 | B12: Global · Breadcrumbs are 12px where the design says 14px | C12: Typography | D12: Minor | E12: Figma: The breadcrumb is 14px — its trail in #374151, the current page in #1f2937. Built: 12px, with the trail in #6b7280 and the current page in #374151. Two steps lighter and a size down, on every screen that has a breadcrumb. | F12: Set the breadcrumb to 14px and restore the two colours. | G12: https://www.figma.com/design/evmNmlK8g4VYwJVu2FwSGV/MoSJE-Portal--Handoff-?node-id=8664-51029 | H12: https://smile-admin-dev.mosje.in/users | I12: Open | L12: env: dev · Scope: Global — fix once, lands everywhere | M12: Global
A13: SMB-GLOBAL-012 | B13: Global · Footer links are smaller and lighter than drawn | C13: Typography | D13: Minor | E13: Figma: Terms & Conditions and Privacy Policy are 14px Medium. Built: 12px Regular, on every screen. | F13: Set the footer links to 14px Medium. | G13: https://www.figma.com/design/evmNmlK8g4VYwJVu2FwSGV/MoSJE-Portal--Handoff-?node-id=8664-51029 | H13: https://smile-admin-dev.mosje.in/users | I13: Open | L13: env: dev · Scope: Global — fix once, lands everywhere | M13: Global
... A61: SMB-SA-CITYL2-001 | B61: City Profiling — district list | C61: Components & States | D61: Minor | E61: Figma: Three KPI cards (Cities Selected, Total Identified, Total Rehabilitated), and the table sits in a bordered card with a tinted, rounded header band. Built: Five KPI cards — Fund Disbursed and Fund Utilised are added, as on the state list — and the table has no card border and a flat header band. City names are underlined links where the design draws them as plain navy. | F61: Same decision as the state list (S25): add the two cards to the design or drop them. Restore the table's card and its header band. | G61: https://www.figma.com/design/evmNmlK8g4VYwJVu2FwSGV/MoSJE-Portal--Handoff-?node-id=51891-441685 | H61: https://smile-admin-dev.mosje.in/city-profiling/1 | I61: Open | L61: env: dev | M61: Screen

Sheet Coverage – SMILE Beggary
A1: Screen | B1: Section | C1: Figma URL | D1: Has Design? | E1: Built? | F1: QC Status | G1: # Findings | H1: Notes
A2: signin — Sign In | B2: signin | C2: https://www.figma.com/design/evmNmlK8g4VYwJVu2FwSGV/MoSJE-Portal--Handoff-?node-id=8383-55268 | D2: Yes | E2: Yes | F2: In Review | G2: =COUNTIF('SMILE Beggary'!$B:$B,"Sign In")
A3: signin — Sign In — Implementing Agency (OTP) | B3: signin | C3: https://www.figma.com/design/evmNmlK8g4VYwJVu2FwSGV/MoSJE-Portal--Handoff-?node-id=8383-54485 | D3: Yes | E3: Yes | F3: In Review | G3: =COUNTIF('SMILE Beggary'!$B:$B,"Sign In — Implementing Agency (OTP)")
A4: signin — Choose Portal | B4: signin | C4: https://www.figma.com/design/evmNmlK8g4VYwJVu2FwSGV/MoSJE-Portal--Handoff-?node-id=8383-55528 | D4: Yes | E4: Yes | F4: In Review | G4: =COUNTIF('SMILE Beggary'!$B:$B,"Choose Portal")
A5: signin — Sign In (landing) | B5: signin | C5: https://www.figma.com/design/evmNmlK8g4VYwJVu2FwSGV/MoSJE-Portal--Handoff-?node-id=8383-55268 | D5: Yes | E5: Yes | F5: In Review | G5: =COUNTIF('SMILE Beggary'!$B:$B,"Sign In (landing)")
A6: super-admin — Audit Log | B6: super-admin | C6: https://www.figma.com/design/evmNmlK8g4VYwJVu2FwSGV/MoSJE-Portal--Handoff-?node-id=51868-193450 | D6: Yes | E6: Yes | F6: In Review | G6: =COUNTIF('SMILE Beggary'!$B:$B,"Audit Log")
A7: super-admin — IA List | B7: super-admin | C7: https://www.figma.com/design/evmNmlK8g4VYwJVu2FwSGV/MoSJE-Portal--Handoff-?node-id=51699-172678 | D7: Yes | E7: Yes | F7: In Review | G7: =COUNTIF('SMILE Beggary'!$B:$B,"IA List")
A8: super-admin — City Profiling | B8: super-admin | C8: https://www.figma.com/design/evmNmlK8g4VYwJVu2FwSGV/MoSJE-Portal--Handoff-?node-id=51891-441340 | D8: Yes | E8: Yes | F8: In Review | G8: =COUNTIF('SMILE Beggary'!$B:$B,"City Profiling")
A9: super-admin — Rehab Data | B9: super-admin | C9: https://www.figma.com/design/evmNmlK8g4VYwJVu2FwSGV/MoSJE-Portal--Handoff-?node-id=51742-166982 | D9: Yes | E9: Yes | F9: In Review | G9: =COUNTIF('SMILE Beggary'!$B:$B,"Rehab Data")
A10: super-admin — Skill & Training | B10: super-admin | C10: https://www.figma.com/design/evmNmlK8g4VYwJVu2FwSGV/MoSJE-Portal--Handoff-?node-id=51742-164435 | D10: Yes | E10: Yes | F10: In Review | G10: =COUNTIF('SMILE Beggary'!$B:$B,"Skill & Training")
A11: super-admin — Consent Forms | B11: super-admin | C11: https://www.figma.com/design/evmNmlK8g4VYwJVu2FwSGV/MoSJE-Portal--Handoff-?node-id=51873-194809 | D11: Yes | E11: Yes | F11: In Review | G11: =COUNTIF('SMILE Beggary'!$B:$B,"Consent Forms")
A12: super-admin — Dashboard | B12: super-admin | C12: https://www.figma.com/design/evmNmlK8g4VYwJVu2FwSGV/MoSJE-Portal--Handoff-?node-id=8664-49264 | D12: Yes | E12: Yes | F12: In Review | G12: =COUNTIF('SMILE Beggary'!$B:$B,"Dashboard")
A13: super-admin — Fund Monitoring - Sanction Order Tracking | B13: super-admin | C13: https://www.figma.com/design/evmNmlK8g4VYwJVu2FwSGV/MoSJE-Portal--Handoff-?node-id=51751-165371 | D13: Yes | E13: Yes | F13: In Review | G13: =COUNTIF('SMILE Beggary'!$B:$B,"Fund Monitoring - Sanction Order Tracking")
A14: super-admin — Master Settings - Geography Masters | B14: super-admin | C14: https://www.figma.com/design/evmNmlK8g4VYwJVu2FwSGV/MoSJE-Portal--Handoff-?node-id=51836-240081 | D14: Yes | E14: Yes | F14: In Review | G14: =COUNTIF('SMILE Beggary'!$B:$B,"Master Settings - Geography Masters")
A15: super-admin — Notifications | B15: super-admin | C15: https://www.figma.com/design/evmNmlK8g4VYwJVu2FwSGV/MoSJE-Portal--Handoff-?node-id=51830-237991 | D15: Yes | E15: Yes | F15: In Review | G15: =COUNTIF('SMILE Beggary'!$B:$B,"Notifications")
A16: super-admin — Performance Statistics | B16: super-admin | C16: https://www.figma.com/design/evmNmlK8g4VYwJVu2FwSGV/MoSJE-Portal--Handoff-?node-id=51563-156833 | D16: Yes | E16: Yes | F16: In Review | G16: =COUNTIF('SMILE Beggary'!$B:$B,"Performance Statistics")
A17: super-admin — Permissions | B17: super-admin | C17: https://www.figma.com/design/evmNmlK8g4VYwJVu2FwSGV/MoSJE-Portal--Handoff-?node-id=51661-156038 | D17: Yes | E17: Yes | F17: In Review | G17: =COUNTIF('SMILE Beggary'!$B:$B,"Permissions")
A18: super-admin — Beneficiary List | B18: super-admin | C18: https://www.figma.com/design/evmNmlK8g4VYwJVu2FwSGV/MoSJE-Portal--Handoff-?node-id=8664-57337 | D18: Yes | E18: Yes | F18: In Review | G18: =COUNTIF('SMILE Beggary'!$B:$B,"Beneficiary List")
A19: super-admin — Roles | B19: super-admin | C19: https://www.figma.com/design/evmNmlK8g4VYwJVu2FwSGV/MoSJE-Portal--Handoff-?node-id=8664-52367 | D19: Yes | E19: Yes | F19: In Review | G19: =COUNTIF('SMILE Beggary'!$B:$B,"Roles")
A20: super-admin — Swashraya (Shelter Homes) | B20: super-admin | C20: https://www.figma.com/design/evmNmlK8g4VYwJVu2FwSGV/MoSJE-Portal--Handoff-?node-id=51723-161681 | D20: Yes | E20: Yes | F20: In Review | G20: =COUNTIF('SMILE Beggary'!$B:$B,"Swashraya (Shelter Homes)")
A21: super-admin — Shelter Occupants | B21: super-admin | C21: https://www.figma.com/design/evmNmlK8g4VYwJVu2FwSGV/MoSJE-Portal--Handoff-?node-id=51712-164958 | D21: Yes | E21: Yes | F21: In Review | G21: =COUNTIF('SMILE Beggary'!$B:$B,"Shelter Occupants")
A22: super-admin — Survey Locations | B22: super-admin | C22: https://www.figma.com/design/evmNmlK8g4VYwJVu2FwSGV/MoSJE-Portal--Handoff-?node-id=8664-55325 | D22: Yes | E22: Yes | F22: In Review | G22: =COUNTIF('SMILE Beggary'!$B:$B,"Survey Locations")
A23: super-admin — Surveyor Mappings | B23: super-admin | C23: https://www.figma.com/design/evmNmlK8g4VYwJVu2FwSGV/MoSJE-Portal--Handoff-?node-id=51699-165683 | D23: Yes | E23: Yes | F23: In Review | G23: =COUNTIF('SMILE Beggary'!$B:$B,"Surveyor Mappings")
A24: super-admin — Users | B24: super-admin | C24: https://www.figma.com/design/evmNmlK8g4VYwJVu2FwSGV/MoSJE-Portal--Handoff-?node-id=8664-51029 | D24: Yes | E24: Yes | F24: In Review | G24: =COUNTIF('SMILE Beggary'!$B:$B,"Users")
A25: super-admin — City Profiling - Level 2 City/District List | B25: super-admin | C25: https://www.figma.com/design/evmNmlK8g4VYwJVu2FwSGV/MoSJE-Portal--Handoff-?node-id=51891-441685 | D25: Yes | E25: Yes | F25: In Review | G25: =COUNTIF('SMILE Beggary'!$B:$B,"City Profiling - Level 2 City/District List")
A26: super-admin — Master Settings - Agency Masters | B26: super-admin | C26: https://www.figma.com/design/evmNmlK8g4VYwJVu2FwSGV/MoSJE-Portal--Handoff-?node-id=51845-184267 | D26: Yes | E26: Yes | F26: In Review | G26: =COUNTIF('SMILE Beggary'!$B:$B,"Master Settings - Agency Masters")
A27: super-admin — Master Settings - Fund Management Masters | B27: super-admin | C27: https://www.figma.com/design/evmNmlK8g4VYwJVu2FwSGV/MoSJE-Portal--Handoff-?node-id=51847-186355 | D27: Yes | E27: Yes | F27: In Review | G27: =COUNTIF('SMILE Beggary'!$B:$B,"Master Settings - Fund Management Masters")
A28: super-admin — Master Settings - Geography Masters | B28: super-admin | C28: https://www.figma.com/design/evmNmlK8g4VYwJVu2FwSGV/MoSJE-Portal--Handoff-?node-id=51836-240081 | D28: Yes | E28: Yes | F28: In Review | G28: =COUNTIF('SMILE Beggary'!$B:$B,"Master Settings - Geography Masters")
A29: super-admin — Master Settings - Operational Masters | B29: super-admin | C29: https://www.figma.com/design/evmNmlK8g4VYwJVu2FwSGV/MoSJE-Portal--Handoff-?node-id=51845-186361 | D29: Yes | E29: Yes | F29: In Review | G29: =COUNTIF('SMILE Beggary'!$B:$B,"Master Settings - Operational Masters")
A30: super-admin — Master Settings - Roles & Permission Masters | B30: super-admin | C30: https://www.figma.com/design/evmNmlK8g4VYwJVu2FwSGV/MoSJE-Portal--Handoff-?node-id=51845-182519 | D30: Yes | E30: Yes | F30: In Review | G30: =COUNTIF('SMILE Beggary'!$B:$B,"Master Settings - Roles & Permission Masters")
A31: super-admin — Master Settings - Survey Questionnaire Masters | B31: super-admin | C31: https://www.figma.com/design/evmNmlK8g4VYwJVu2FwSGV/MoSJE-Portal--Handoff-?node-id=51845-183410 | D31: Yes | E31: Yes | F31: In Review | G31: =COUNTIF('SMILE Beggary'!$B:$B,"Master Settings - Survey Questionnaire Masters")
A32: super-admin — Permissions | B32: super-admin | C32: https://www.figma.com/design/evmNmlK8g4VYwJVu2FwSGV/MoSJE-Portal--Handoff-?node-id=51661-156038 | D32: Yes | E32: Yes | F32: In Review | G32: =COUNTIF('SMILE Beggary'!$B:$B,"Permissions")
A33: super-admin — Roles | B33: super-admin | C33: https://www.figma.com/design/evmNmlK8g4VYwJVu2FwSGV/MoSJE-Portal--Handoff-?node-id=8664-52367 | D33: Yes | E33: Yes | F33: In Review | G33: =COUNTIF('SMILE Beggary'!$B:$B,"Roles")
A34: super-admin — Roles - Create New Role | B34: super-admin | C34: https://www.figma.com/design/evmNmlK8g4VYwJVu2FwSGV/MoSJE-Portal--Handoff-?node-id=51661-158685 | D34: Yes | E34: Yes | F34: In Review | G34: =COUNTIF('SMILE Beggary'!$B:$B,"Roles - Create New Role")
A35: super-admin — Beneficiary section - Add Shelter Homes | B35: super-admin | C35: https://www.figma.com/design/evmNmlK8g4VYwJVu2FwSGV/MoSJE-Portal--Handoff-?node-id=51712-166102 | D35: Yes | E35: Yes | F35: In Review | G35: =COUNTIF('SMILE Beggary'!$B:$B,"Beneficiary section - Add Shelter Homes")
A36: super-admin — Swashraya - Edit Shelter Home | B36: super-admin | C36: https://www.figma.com/design/evmNmlK8g4VYwJVu2FwSGV/MoSJE-Portal--Handoff-?node-id=51742-163249 | D36: Yes | E36: Yes | F36: In Review | G36: =COUNTIF('SMILE Beggary'!$B:$B,"Swashraya - Edit Shelter Home")
A37: super-admin — Survey Locations section - Surveyor | B37: super-admin | C37: https://www.figma.com/design/evmNmlK8g4VYwJVu2FwSGV/MoSJE-Portal--Handoff-?node-id=51687-156971 | D37: Yes | E37: Yes | F37: In Review | G37: =COUNTIF('SMILE Beggary'!$B:$B,"Survey Locations section - Surveyor")
A38: super-admin — Users | B38: super-admin | C38: https://www.figma.com/design/evmNmlK8g4VYwJVu2FwSGV/MoSJE-Portal--Handoff-?node-id=8664-51029 | D38: Yes | E38: Yes | F38: In Review | G38: =COUNTIF('SMILE Beggary'!$B:$B,"Users")
A39: super-admin — Users - Add User | B39: super-admin | C39: https://www.figma.com/design/evmNmlK8g4VYwJVu2FwSGV/MoSJE-Portal--Handoff-?node-id=8664-52311 | D39: Yes | E39: Yes | F39: In Review | G39: =COUNTIF('SMILE Beggary'!$B:$B,"Users - Add User")
A40: central-authority — Audit Log | B40: central-authority | C40: https://www.figma.com/design/evmNmlK8g4VYwJVu2FwSGV/MoSJE-Portal--Handoff-?node-id=51868-193450 | D40: Yes | E40: Yes | F40: In Review | G40: =COUNTIF('SMILE Beggary'!$B:$B,"Audit Log")
...

Sheet NMBA
A1: ID | B1: Screen | C1: Category | D1: Severity | E1: Issue (Design → Built) | F1: Recommended Fix (Dev) | G1: Figma URL | H1: Live URL | I1: Status | J1: Assignee | K1: Date | L1: Notes | M1: Scope
A2: NMB-GLOBAL-001 | B2: Global · Sidebar navigation labels fail AA contrast | C2: Color & Token | D2: Blocker | E2: Figma: Every navigation label is #1F2937 on the panel's #F9FAFB ground - 14.05:1 - and the selected item is #003366 on an #E5EFF9 pill, 10.84:1. Sampled off the design frame beside five nav rows. → Live: Every unselected navigation label is #9CA3AF. That is 2.43:1, where WCAG 2.2 AA requires 4.5:1 for text this size. It reads as a disabled control, and it is the same in the citizen shell and in all three admin roles. (Re-measured in the DOM on the live build, 2026-09-11. An earlier wording put this at 2.54:1 by assuming a white ground; the sidebar has no background of its own - the <aside> computes to transparent and the body behind it is #F9FAFB, which the rendered pixel behind a label confirms. The real ratio is slightly WORSE than published, not better.) | F2: Set the unselected label to the design's #1F2937. If a quieter resting state is wanted, #4B5563 clears comfortably at 7.23:1 on this ground and #6B7280 is the lightest neutral that still passes, at 4.63:1; #9CA3AF cannot be used for text on #F9FAFB at any size. | G2: https://www.figma.com/design/evmNmlK8g4VYwJVu2FwSGV/MoSJE-Portal--Handoff-?node-id=52061-126900 | H2: https://nmba-admin-dev.mosje.in/user-management | I2: Done | L2: env: dev · Scope: Global — fix once, lands everywhere | M2: Global
A3: NMB-GLOBAL-002 | B3: Global · The GIGW accessibility toolset is missing from the masthead | C3: Components & States | D3: Blocker | E3: Figma: The blue government bar carries the mandated inline set: A- / A / A+ text-size controls with the current size shown selected, a contrast toggle, an accessibility icon, and a globe with the language named in words ('English'). → Live: The bar carries only an accessibility glyph, which opens a third-party panel, and a bare two-script glyph for language. The text-size controls and the contrast toggle are not present anywhere on the page. | F3: Restore the inline A- / A / A+ and contrast controls in the government bar, and label the language control with the language name as the design does. GIGW 3.0 treats this set as a masthead requirement, so its absence is a compliance gap on every screen, not a styling preference. | G3: https://www.figma.com/design/evmNmlK8g4VYwJVu2FwSGV/MoSJE-Portal--Handoff-?node-id=52061-126900 | H3: https://nmba-admin-dev.mosje.in/user-management | I3: Open | L3: env: dev · Scope: Global — fix once, lands everywhere | M3: Global
A4: NMB-GLOBAL-003 | B4: Global · Admin sidebar navigation icons are absent | C4: Content & Iconography | D4: Major | E4: Figma: Every admin navigation item pairs a 24px Material Symbols icon at #003366 with its label - widgets, event, group_add, article_shortcut, task and so on - and the icon sits 32px from the panel edge. → Live: The admin sidebar draws label-only rows with a thin tree-branch connector line in the icon's place. No item has an icon. The citizen shell DOES carry its icons, so the two shells disagree with each other as well as with the design. | F4: Add the navigation icon to each admin sidebar item, using the same Material Symbols set and #003366 the citizen shell already uses, and drop the connector line the design does not have. | G4: https://www.figma.com/design/evmNmlK8g4VYwJVu2FwSGV/MoSJE-Portal--Handoff-?node-id=52061-126900 | H4: https://nmba-admin-dev.mosje.in/user-management | I4: Open | L4: env: dev · Scope: Global — fix once, lands everywhere | M4: Global
A5: NMB-GLOBAL-004 | B5: Global · The ministry lockup drops its third line and changes colour | C5: Typography | D5: Major | E5: Figma: Three lines, all #1F2937: 'Government of India' at 12px Medium, 'Ministry of Social Justice & Empowerment' at 14px Medium, and 'Department of Social Justice & Empowerment' at 20px Bold as the emphasised line. → Live: Two lines at #374151: 'Government of India' at 12px Medium, and 'Ministry of Social Justice & Empowerment' promoted to 20px Bold. The Department line is not rendered. The sign-in page does draw all three, so the authenticated shell also disagrees with the portal's own login screen. | F5: Render the third line and set the lockup to #1F2937, matching the sign-in page and the design. The emphasised line is the Department, not the Ministry. | G5: https://www.figma.com/design/evmNmlK8g4VYwJVu2FwSGV/MoSJE-Portal--Handoff-?node-id=52061-126900 | H5: https://nmba-admin-dev.mosje.in/user-management | I5: Open | L5: env: dev · Scope: Global — fix once, lands everywhere | M5: Global
A6: NMB-GLOBAL-005 | B6: Global · Row action controls lose their button and change colour | C6: Components & States | D6: Major | E6: Figma: Row actions are the library's own Icon Button (Size=Small, Type=Outlined, Color=Neutral): 32x32, a 1px #E5E7EB outline at radius 8, the edit glyph #003366 and the delete glyph #EC5042. Read off the component's own nodes in the design file, not sampled - an earlier wording said radius 6. → Live: The actions are bare glyphs with no button around them - two 24px SVG images on User Management - and the edit glyph is filled #ED8525 (read from the served file, not sampled off a screenshot), an amber that appears nowhere in the NMBA token set. On three of the NAPDDR screens - State, District and Block Committee - the same actions become three outlined TEXT buttons instead (View / Edit / Delete, 1px border, radius 6), and on Important Documents they are a third thing again: real buttons wrapping tabler icons with no border at all. Verified on the live build, 2026-09-11. Committee Reports carries no row actions. | F6: Restore the library's Icon Button - 32x32, 1px #E5E7EB, radius 8 - and set the edit glyph to #003366. One icon treatment has to hold across every screen - the same glyph set, the same button, the same two colours - rather than icon-buttons on some screens, amber glyphs on others and text buttons on three of the NAPDDR screens. | G6: https://www.figma.com/design/evmNmlK8g4VYwJVu2FwSGV/MoSJE-Portal--Handoff-?node-id=52061-126900 | H6: https://nmba-admin-dev.mosje.in/user-management | I6: Open | L6: env: dev · Scope: Global — fix once, lands everywhere | M6: Global
A7: NMB-GLOBAL-006 | B7: Global · Previous and next are a hyphen and a plus sign | C7: Content & Iconography | D7: Major | E7: Figma: The pager runs a left chevron, the page numbers with the current one in a rounded outlined chip, an ellipsis, the last page, and a right chevron. → Live: The two step controls render as '-' and '+'. A minus and a plus read as decrease and increase, not as previous and next page. (The pager DOES carry an ellipsis and a last-page number - checked on the live build 2026-09-11, which shows '- 1 2 3 ... 1,393 +'. An earlier wording of this finding said it did not; that was read off a capture and was wrong.) | F7: Use the chevrons the design specifies for the step controls, and show the ellipsis and last page so a reader can tell how long the list is. | G7: https://www.figma.com/design/evmNmlK8g4VYwJVu2FwSGV/MoSJE-Portal--Handoff-?node-id=52092-136433 | H7: https://nmba-admin-dev.mosje.in/napddr/state-committee | I7: Open | L7: env: dev · Scope: Global — fix once, lands everywhere | M7: Global
A8: NMB-GLOBAL-009 | B8: Global · Table row height is inconsistent across the portal | C8: Layout & Spacing | D8: Major | E8: Figma: Every data cell in the design is 56px tall - all 50 of them, exactly, on this frame - and every header cell is 52px. Counted off the frame's own nodes, not estimated; an earlier wording said 'a steady 45-55px', which understated how uniform the design actually is. → Live: Measured row heights run 41px on User Management, 53px on most lists, 57px on Important Documents, 65px on the NAPDDR screens, 85px on Best Practices and 153px on the Ministries dashboard - the same component at more than three times the height from one screen to the next. Header rows vary too, from 38px to 85px. | F8: Set one row height for the table component and let it apply everywhere; where a cell wraps to two lines, let the row grow from that one value rather than redefining it per screen. | G8: https://www.figma.com/design/evmNmlK8g4VYwJVu2FwSGV/MoSJE-Portal--Handoff-?node-id=52051-161871 | H8: https://nmba-admin-dev.mosje.in/ministries-dashboard | I8: Open | L8: env: dev · Scope: Global — fix once, lands everywhere | M8: Global
A9: NMB-GLOBAL-039 | B9: Global · The sidebar panel and every row in it are built to different metrics | C9: Layout & Spacing | D9: Major | E9: Figma: The panel is 300px wide with 16px of padding all round and a 1px #E5E7EB edge, and it holds rows that are 268x48 at radius 16, each padded 12px top and bottom and 16px left and right, with an 8px gap between a row's icon and its label. → Live: The panel is 288px with no padding of its own and a 1px #D1D5DB edge, and its rows are 245x36 at radius 10, padded 8px and 12px. Every row is affected, not only the selected one: a row is a quarter shorter than designed, 23px narrower, on a smaller radius, and indented to x30 instead of the design's x16. Read from the DOM on the live build and from the design frame's own nodes, 2026-09-11. | F9: Build the sidebar to the design's metrics: a 300px panel padded 16, rows 268x48 at radius 16 padded 12/16. This is the fifth finding on this one component and the one that makes the others land - NMB-GLOBAL-001 (label colour), NMB-GLOBAL-003 (missing icons and the connector line the design does not draw), NMB-GLOBAL-015 (the selected row's weight and shape) and NMB-GLOBAL-038 (the 60px item rhythm). Treat them as one piece of work against one component rather than five separate tickets; the sidebar does not match the design until all five land. | G9: https://www.figma.com/design/evmNmlK8g4VYwJVu2FwSGV/MoSJE-Portal--Handoff-?node-id=52061-126900 | H9: https://nmba-admin-dev.mosje.in/user-management | I9: Open | L9: env: dev · Scope: Global — fix once, lands everywhere | M9: Global
A10: NMB-GLOBAL-040 | B10: Global · The table's header band, cell padding and dividers are all different from the design | C10: Layout & Spacing | D10: Major | E10: Figma: The table sits in a #FFFFFF container with a 1px #E5E7EB edge at radius 12. Its header is a band: 52px tall, filled #F9FAFB, each cell padded 16px top and bottom and 24px left and right. Data cells are 56px tall, padded 12/24, and separated by a 1px #F3F4F6 rule. → Live: The header has no fill at all - it is transparent, so there is no band, just text above rows - and it is 38px instead of 52. Every cell, header and data alike, is padded 8/16 where the design says 16/24 and 12/24, which is what makes the rows 41px instead of 56. The row rule is #E5E7EB rather than #F3F4F6, a heavier line than the design draws, and the container is radius 6 against the design's 12. Read from the DOM on the live build, 2026-09-11. | F10: Build the table to the design's own component: a radius-12 container, a 52px #F9FAFB header band padded 16/24, 56px data cells padded 12/24, and a #F3F4F6 row rule. This is the finding the other table findings hang off - NMB-GLOBAL-009 (row heights), NMB-GLOBAL-010 (cell colour), NMB-GLOBAL-005 (row actions), NMB-GLOBAL-035 (the extra wrapper), NMB-GLOBAL-036 (a column too narrow for its date) and NMB-SCREEN-030 (action order). The cell padding alone accounts for most of the height difference, so fixing it fixes -009 across the portal. | G10: https://www.figma.com/design/evmNmlK8g4VYwJVu2FwSGV/MoSJE-Portal--Handoff-?node-id=52061-126900 | H10: https://nmba-admin-dev.mosje.in/user-management | I10: Open | L10: env: dev · Scope: Global — fix once, lands everywhere | M10: Global
A11: NMB-GLOBAL-041 | B11: Global · The masthead's marks are the wrong size, and the co-branding is one flattened image | C11: Layout & Spacing | D11: Major | E11: Figma: The National Emblem is 32x52, sitting 30px below the band's top edge. The co-branding is two separate marks, each 40px tall - Digital India at x917, 102 wide, and the SAMAVESH lockup at x1043, 188 wide - together spanning 314px and ending at x1231. The band's lower edge is 1px #F3F4F6. → Live: In the ADMIN shell the National Emblem is 49x80 - about 53% larger on both axes - and sits 24px higher, at y46. The co-branding is not two marks but ONE raster image, 440x56 at x792: 40% wider, 16px taller and starting 125px further left than the design places it, with Digital India and SAMAVESH baked into a single file whose alt text is one 83-character string. The band's lower edge is 1px #D1D5DB against the design's #F3F4F6 - the same substitution the sidebar makes. The CITIZEN shell is worse on the same band: the emblem is 39x64 against the same designed 32x52, the band is 106px tall against 94, and the MINISTRY NAME ITSELF is a 496x56 raster image where the design sets it as three lines of live text. A portal that carries a language control cannot translate a picture of its own name. Read from the DOM on the live build, 2026-09-11. | F11: Draw the National Emblem at the design's 32x52 in its designed position, and compose the co-branding from the two marks the design uses rather than one flattened picture - a single image cannot be scaled per breakpoint, cannot be themed, and gives a screen reader one long string where the design has two named marks. On the citizen shell the ministry name has to come back as text for the same reason, and more urgently: it is the department's own name, on a bilingual portal. Set the band's lower edge to #F3F4F6. Note that the emblem is the National Emblem of India: its proportions are not ours to adjust, and the estate's own rule is that it ships at 3x the largest surface that renders it rather than being scaled up from a smaller file. | G11: https://www.figma.com/design/evmNmlK8g4VYwJVu2FwSGV/MoSJE-Portal--Handoff-?node-id=52061-126900 | H11: https://nmba-admin-dev.mosje.in/user-management | I11: Open | L11: env: dev · Scope: Global — fix once, lands everywhere | M11: Global
A12: NMB-GLOBAL-044 | B12: Global · The search field is the only thing in the portal not set in Noto Sans | C12: Typography | D12: Major | E12: Figma: The field is 938x40 at radius 8 with a 1px #E5E7EB edge, and its placeholder is 14px Noto Sans Regular #374151 - the same face, size and grey as every other field in the design. → Live: The field renders in POPPINS at 16px #000000, in a box 768x43 at radius 6. Counted in the DOM on 2026-09-11: of 147 rendered elements on User Management exactly ONE is not Noto Sans, and it is this input; the same is true on Important Documents. So a single control in the portal is set in a different typeface, a size larger than the design, and in pure black rather than the #374151 the design uses for placeholder text. | F12: Remove the Poppins declaration - it is one rule and it is the only thing importing that family - and let the field inherit Noto Sans at 14px #374151. The estate's standing instruction is Noto Sans across all government properties and no other family introduced. While the rule is being changed, the box wants the design's 40px height and radius 8 rather than 43 and 6. | G12: https://www.figma.com/design/evmNmlK8g4VYwJVu2FwSGV/MoSJE-Portal--Handoff-?node-id=52061-126900 | H12: https://nmba-admin-dev.mosje.in/user-management | I12: Open | L12: env: dev · Scope: Global — fix once, lands everywhere | M12: Global
A13: NMB-GLOBAL-045 | B13: Global · Primary and secondary buttons are built to different metrics | C13: Components & States | D13: Major | E13: Figma: Buttons are 40px tall at radius 8, padded 8-10px vertically and 16/24 horizontally, with the label at 14px Medium: the primary filled #003366 with a #FFFFFF label, the secondary a 1px #003366 outline with a #003366 label. → Live: The primary 'Add User' is 36px tall at radius 4 - half the design's radius - padded 0/18 with its label at weight 600 rather than Medium. The secondary export buttons are 38px at radius 8. So no button in the toolbar is the height the design draws, and the primary and secondary disagree with each other on radius as well as with the design. | F13: Use one button component at the design's 40px height and radius 8, with the label at Medium. The primary's radius 4 is the outlier - every other rounded thing on the screen is 6, 8, 10 or 16, so this is a fifth radius nobody chose. | G13: https://www.figma.com/design/evmNmlK8g4VYwJVu2FwSGV/MoSJE-Portal--Handoff-?node-id=52061-126900 | H13: https://nmba-admin-dev.mosje.in/user-management | I13: Open | L13: env: dev · Scope: Global — fix once, lands everywhere | M13: Global
A14: NMB-GLOBAL-051 | B14: Global · Colours are typed as literals rather than bound to tokens, so the build has its own palette | C14: Color & Token | D14: Major | E14: Figma: The design works from a published token contract of 33 colours - #003366, #1F2937, #E5E7EB, #D1D5DB and the rest - and a form field's edge is the contract's #D1D5DB. → Live: The build paints 110 distinct colours across the 51 captured screens. Twenty-seven of them are design values; THIRTY-FIVE more sit within 24 points of one, which is close enough to look right in review and far enough to be a different literal in the code. The field anchored here is edged #CED4DA against the contract's #D1D5DB - three points apart, on 16 fields across four screens. The largest is #9CA3AF where the design frames use #94A3B8, on 1,471 elements across all 51 screens; then #0A2C53 for #002244 on 201, #D64539 for #EC5042 on 124 across seven screens, #DBEAFE for #D2E3FC on 100, and #217A39 for #2E7D32 on 88. Read from the DOM on the live build, 2026-09-12; the full table is docs/audit/nmba-colour-drift.md. | F14: This is one fix, not thirty-five: bind every colour to its token instead of typing the value. Six findings in this report each name a single instance - the KPI tint (NMB-GLOBAL-012), the activity card edge (NMB-SCREEN-046), the facility card button (NMB-SCREEN-019), the facility chip (NMB-SCREEN-021), the sheet border (NMB-SCREEN-042) and the status labels (NMB-SCREEN-050) - and each of those is this same defect seen once. Correcting them one at a time leaves the next thirty-five to be found by eye. A three-point difference cannot be reviewed reliably by anyone, which is exactly why the values have to come from the tokens. | G14: https://www.figma.com/design/evmNmlK8g4VYwJVu2FwSGV/MoSJE-Portal--Handoff-?node-id=52066-127999 | I14: Open | L14: env: dev · Scope: Global — fix once, lands everywhere | M14: Global
A15: NMB-GLOBAL-007 | B15: Global · Dropdowns are the browser's own select, not the design system's | C15: Components & States | D15: Minor | E15: Figma: Every dropdown is the design-system select: a rounded bordered field with its own chevron and the label at 14px #1F2937. → Live: The rows-per-page control, the facility filter and the three activity filters render as an unstyled native <select> with the operating system's chevron and its own border radius, so they look different on every browser and different from every other control on the page. | F15: Skin these with the design-system select so their border, radius, type and chevron match the rest of the interface. | G15: https://www.figma.com/design/evmNmlK8g4VYwJVu2FwSGV/MoSJE-Portal--Handoff-?node-id=52092-136433 | H15: https://nmba-admin-dev.mosje.in/napddr/state-committee | I15: Open | L15: env: dev · Scope: Global — fix once, lands everywhere | M15: Global
A16: NMB-GLOBAL-008 | B16: Global · The search magnifier is missing, or sits on the wrong side | C16: Content & Iconography | D16: Minor | E16: Figma: Every search field carries a magnifier inside its left edge, ahead of the placeholder. → Live: Checked screen by screen on the live build, 2026-09-11: the magnifier is absent on User Management, the Ministries dashboard, all four NAPDDR screens and Facilities, and on Important Documents, Pledge Reports, List of SNO and the Nasha Mukti Mitr Report it is drawn inside the RIGHT edge instead. So the same control takes three different forms across the portal as well as differing from the design. | F16: Put the magnifier inside the left edge of every search field, as the design does. | G16: https://www.figma.com/design/evmNmlK8g4VYwJVu2FwSGV/MoSJE-Portal--Handoff-?node-id=52070-443098 | H16: https://nmba-admin-dev.mosje.in/important-documents | I16: Open | L16: env: dev · Scope: Global — fix once, lands everywhere | M16: Global
A17: NMB-GLOBAL-010 | B17: Global · Table cell text is lighter than the design | C17: Color & Token | D17: Minor | E17: Figma: Cell values are #1F2937, the same near-black the rest of the body copy uses. → Live: Cell values are #4B5563. It still clears AA, but it makes the data quieter than its own column headers, which the design does not do. | F17: Set cell values to #1F2937 and leave #4B5563 for secondary lines inside a cell. | G17: https://www.figma.com/design/evmNmlK8g4VYwJVu2FwSGV/MoSJE-Portal--Handoff-?node-id=52061-126900 | H17: https://nmba-admin-dev.mosje.in/user-management | I17: Open | L17: env: dev · Scope: Global — fix once, lands everywhere | M17: Global
A18: NMB-GLOBAL-011 | B18: Global · The page title is a lighter grey than the design | C18: Color & Token | D18: Minor | E18: Figma: The page title is 24px SemiBold #1F2937. → Live: The page title is 24px 600 #374151 - the right size and weight, a lighter colour. | F18: Set the page title to #1F2937. | G18: https://www.figma.com/design/evmNmlK8g4VYwJVu2FwSGV/MoSJE-Portal--Handoff-?node-id=52061-126900 | H18: https://nmba-admin-dev.mosje.in/user-management | I18: Open | L18: env: dev · Scope: Global — fix once, lands everywhere | M18: Global
